2020-12-15 18:03:03,570 ERROR 645780 140361285973760 in app 1761 Exception on / [GET]
Traceback (most recent call last):
  File "/home/abelit/.pyenv/versions/3.5.6/lib/python3.5/site-packages/flask/app.py", line 2292, in wsgi_app
    response = self.full_dispatch_request()
  File "/home/abelit/.pyenv/versions/3.5.6/lib/python3.5/site-packages/flask/app.py", line 1816, in full_dispatch_request
    return self.finalize_request(rv)
  File "/home/abelit/.pyenv/versions/3.5.6/lib/python3.5/site-packages/flask/app.py", line 1833, in finalize_request
    response = self.process_response(response)
  File "/home/abelit/.pyenv/versions/3.5.6/lib/python3.5/site-packages/flask/app.py", line 2112, in process_response
    response = handler(response)
TypeError: middle_end_request() takes 0 positional arguments but 1 was given
2020-12-15 18:03:09,347 ERROR 645780 140361208952576 in app 1761 Exception on /api [GET]
Traceback (most recent call last):
  File "/home/abelit/.pyenv/versions/3.5.6/lib/python3.5/site-packages/flask/app.py", line 2292, in wsgi_app
    response = self.full_dispatch_request()
  File "/home/abelit/.pyenv/versions/3.5.6/lib/python3.5/site-packages/flask/app.py", line 1816, in full_dispatch_request
    return self.finalize_request(rv)
  File "/home/abelit/.pyenv/versions/3.5.6/lib/python3.5/site-packages/flask/app.py", line 1833, in finalize_request
    response = self.process_response(response)
  File "/home/abelit/.pyenv/versions/3.5.6/lib/python3.5/site-packages/flask/app.py", line 2112, in process_response
    response = handler(response)
TypeError: middle_end_request() takes 0 positional arguments but 1 was given
2020-12-15 18:04:18,596 ERROR 647453 140234819233536 in app 1761 Exception on / [GET]
Traceback (most recent call last):
  File "/home/abelit/.pyenv/versions/3.5.6/lib/python3.5/site-packages/flask/app.py", line 2292, in wsgi_app
    response = self.full_dispatch_request()
  File "/home/abelit/.pyenv/versions/3.5.6/lib/python3.5/site-packages/flask/app.py", line 1816, in full_dispatch_request
    return self.finalize_request(rv)
  File "/home/abelit/.pyenv/versions/3.5.6/lib/python3.5/site-packages/flask/app.py", line 1833, in finalize_request
    response = self.process_response(response)
  File "/home/abelit/.pyenv/versions/3.5.6/lib/python3.5/site-packages/flask/app.py", line 2112, in process_response
    response = handler(response)
TypeError: middle_end_request() takes 0 positional arguments but 1 was given
2020-12-15 18:04:22,254 ERROR 647453 140234810840832 in app 1761 Exception on /api [GET]
Traceback (most recent call last):
  File "/home/abelit/.pyenv/versions/3.5.6/lib/python3.5/site-packages/flask/app.py", line 2292, in wsgi_app
    response = self.full_dispatch_request()
  File "/home/abelit/.pyenv/versions/3.5.6/lib/python3.5/site-packages/flask/app.py", line 1816, in full_dispatch_request
    return self.finalize_request(rv)
  File "/home/abelit/.pyenv/versions/3.5.6/lib/python3.5/site-packages/flask/app.py", line 1833, in finalize_request
    response = self.process_response(response)
  File "/home/abelit/.pyenv/versions/3.5.6/lib/python3.5/site-packages/flask/app.py", line 2112, in process_response
    response = handler(response)
TypeError: middle_end_request() takes 0 positional arguments but 1 was given
2020-12-15 18:04:26,238 ERROR 647453 140234819233536 in app 1761 Exception on /api/vq [GET]
Traceback (most recent call last):
  File "/home/abelit/.pyenv/versions/3.5.6/lib/python3.5/site-packages/flask/app.py", line 2292, in wsgi_app
    response = self.full_dispatch_request()
  File "/home/abelit/.pyenv/versions/3.5.6/lib/python3.5/site-packages/flask/app.py", line 1816, in full_dispatch_request
    return self.finalize_request(rv)
  File "/home/abelit/.pyenv/versions/3.5.6/lib/python3.5/site-packages/flask/app.py", line 1833, in finalize_request
    response = self.process_response(response)
  File "/home/abelit/.pyenv/versions/3.5.6/lib/python3.5/site-packages/flask/app.py", line 2112, in process_response
    response = handler(response)
TypeError: middle_end_request() takes 0 positional arguments but 1 was given
2020-12-15 18:04:32,850 ERROR 647453 140234810840832 in app 1761 Exception on /api/v1/ehr [GET]
Traceback (most recent call last):
  File "/home/abelit/.pyenv/versions/3.5.6/lib/python3.5/site-packages/flask/app.py", line 2292, in wsgi_app
    response = self.full_dispatch_request()
  File "/home/abelit/.pyenv/versions/3.5.6/lib/python3.5/site-packages/flask/app.py", line 1816, in full_dispatch_request
    return self.finalize_request(rv)
  File "/home/abelit/.pyenv/versions/3.5.6/lib/python3.5/site-packages/flask/app.py", line 1833, in finalize_request
    response = self.process_response(response)
  File "/home/abelit/.pyenv/versions/3.5.6/lib/python3.5/site-packages/flask/app.py", line 2112, in process_response
    response = handler(response)
TypeError: middle_end_request() takes 0 positional arguments but 1 was given
